Workbook

Sheet произв
A1: Наименование
A2: --
A3: 27 юа
A4: 2х3
A5: Althaus
A6: APACER
A7: ATSN group
A8: Bandinelli
A9: Brille
A10: Canti Prosecco
A11: Fozzy
A12: IT-BOX
... A131: Югконтракт

Sheet уид произв
A1: Наименование | B1: УИД | C1: Родитель
A2: Віват | B2: 602b861c-2596-11ea-a23b-00155dd08a09
A3: Імпорт Офіс | B3: 602b861d-2596-11ea-a23b-00155dd08a09
A4: СЕРВІС ПРО | B4: d3d228aa-264f-11ea-a23b-00155dd08a09
A5: Метро | B5: a0d7129c-298a-11ea-a23b-00155dd08a09
A6: Орімі | B6: ca0710a5-2d4b-11ea-a23b-00155dd08a09
A7: Люстдорф | B7: ddb1a4d3-2d54-11ea-a23b-00155dd08a09
A8: розетка | B8: 96e4ff39-2d5e-11ea-a23b-00155dd08a09
A9: приват інвест | B9: 13812237-2e36-11ea-a23b-00155dd08a09
A10: Епіцентр | B10: f3756d12-35fa-11ea-a23b-00155dd08a09
A11: Зінеко | B11: eae96084-36a8-11ea-a23b-00155dd08a09
A12: АНКОР-ДА | B12: aa93fcdf-36af-11ea-a23b-00155dd08a09
A13: СТС-Групп | B13: 5f4158a1-3780-11ea-a23b-00155dd08a09
... A131: Євромарк | B131: ef1a723f-639b-11ea-a240-00155d00f0a7

Sheet тм уид
A1: Наименование | B1: УИД | C1: Родитель
A2: AXENT | B2: f2e4e0c9-2598-11ea-a23b-00155dd08a09
A3: BRUNNEN | B3: f2e4e0ca-2598-11ea-a23b-00155dd08a09
A4: CENTROPEN | B4: f2e4e0cb-2598-11ea-a23b-00155dd08a09
A5: edding | B5: f2e4e0cc-2598-11ea-a23b-00155dd08a09
A6: GoPack | B6: f2e4e0cd-2598-11ea-a23b-00155dd08a09
A7: KITE | B7: f2e4e0ce-2598-11ea-a23b-00155dd08a09
A8: KOH-I-NOOR | B8: f2e4e0cf-2598-11ea-a23b-00155dd08a09
A9: KUM | B9: f2e4e0d0-2598-11ea-a23b-00155dd08a09
A10: Unimax | B10: f2e4e0d1-2598-11ea-a23b-00155dd08a09
A11: ГАММА | B11: f2e4e0d2-2598-11ea-a23b-00155dd08a09
A12: МАРКО ПОЛО | B12: f2e4e0d3-2598-11ea-a23b-00155dd08a09
A13: LEGGICOMODO | B13: f2e4e0d4-2598-11ea-a23b-00155dd08a09
... A905: Royal Mix | B905: 37f5f19b-3d11-11ea-a23c-00155dd08a09
A906: 1 | B906: f853491a-3dc5-11ea-a23c-00155dd08a09 | C906: Удаленные
A907: АЛАН | B907: 675c5dda-3de0-11ea-a23c-00155dd08a09
A908: RICE UP | B908: 9b5dd779-3de0-11ea-a23c-00155dd08a09
A909: FELIX | B909: 3a1f5c29-3de1-11ea-a23c-00155dd08a09
A910: WINWAY | B910: b7af0bdd-3de6-11ea-a23c-00155dd08a09
A911: ОЛПАК | B911: a42f7f9a-3de7-11ea-a23c-00155dd08a09
A912: Helios | B912: d01bbeec-3dea-11ea-a23c-00155dd08a09
A913: Wallner | B913: b7118314-3dec-11ea-a23c-00155dd08a09
A914: Розетка | B914: 7c6bcb22-3dee-11ea-a23c-00155dd08a09
A915: Eternum | B915: ce67a169-3df0-11ea-a23c-00155dd08a09
A916: MCCORN | B916: 050194cf-3df4-11ea-a23c-00155dd08a09
A917: TEA HOUSE HERITAGE | B917: 49408e74-3df4-11ea-a23c-00155dd08a09
A918: PRINGLES | B918: 86c81ec2-3df5-11ea-a23c-00155dd08a09
... A1093: HOZZI | B1093: 3841aa9e-63a6-11ea-a240-00155d00f0a7

Sheet сопоставление
A1: НаименованиеТМ | B1: ТМ_УИД | C1: Производитель | D1: Производитель_УИД
A2: "Bob Snail" | B2: =INDIRECT(ADDRESS(MATCH(A2,'тм уид'!A:A,0),2, , ,"тм уид")) -> 63eae718-4e54-11ea-a23f-00155dd08a0a | C2: Метро | D2: =INDIRECT(ADDRESS(MATCH(C2,'уид произв'!A:A,0),2, , ,"уид произв")) -> a0d7129c-298a-11ea-a23b-00155dd08a09
A3: 2х3 | B3: =INDIRECT(ADDRESS(MATCH(A3,'тм уид'!A:A,0),2, , ,"тм уид")) -> 315301c0-5317-11ea-a23f-00155dd08a0a | C3: 2х3 | D3: =INDIRECT(ADDRESS(MATCH(C3,'уид произв'!A:A,0),2, , ,"уид произв")) -> 927c4fed-499d-11ea-a23e-00155dd08a09
A4: 7 DAYS | B4: =INDIRECT(ADDRESS(MATCH(A4,'тм уид'!A:A,0),2, , ,"тм уид")) -> 14f1eae0-3b81-11ea-a23c-00155dd08a09 | C4: Метро | D4: =INDIRECT(ADDRESS(MATCH(C4,'уид произв'!A:A,0),2, , ,"уид произв")) -> a0d7129c-298a-11ea-a23b-00155dd08a09
A5: 7UP | B5: =INDIRECT(ADDRESS(MATCH(A5,'тм уид'!A:A,0),2, , ,"тм уид")) -> b35968b5-298a-11ea-a23b-00155dd08a09 | C5: Метро | D5: =INDIRECT(ADDRESS(MATCH(C5,'уид произв'!A:A,0),2, , ,"уид произв")) -> a0d7129c-298a-11ea-a23b-00155dd08a09
A6: 8 ЗЛАКІВ | B6: =INDIRECT(ADDRESS(MATCH(A6,'тм уид'!A:A,0),2, , ,"тм уид")) -> b359685f-298a-11ea-a23b-00155dd08a09 | C6: Метро | D6: =INDIRECT(ADDRESS(MATCH(C6,'уид произв'!A:A,0),2, , ,"уид произв")) -> a0d7129c-298a-11ea-a23b-00155dd08a09
A7: 9230SI | B7: =INDIRECT(ADDRESS(MATCH(A7,'тм уид'!A:A,0),2, , ,"тм уид")) -> d89bbd50-63a4-11ea-a240-00155d00f0a7 | C7: ЕРГОПАК | D7: =INDIRECT(ADDRESS(MATCH(C7,'уид произв'!A:A,0),2, , ,"уид произв")) -> c89940cf-429f-11ea-a23c-00155dd08a09
A8: ACTIMEL | B8: =INDIRECT(ADDRESS(MATCH(A8,'тм уид'!A:A,0),2, , ,"тм уид")) -> ed38b08c-27eb-11ea-a23b-00155dd08a09 | C8: Метро | D8: =INDIRECT(ADDRESS(MATCH(C8,'уид произв'!A:A,0),2, , ,"уид произв")) -> a0d7129c-298a-11ea-a23b-00155dd08a09
A9: AERO | B9: =INDIRECT(ADDRESS(MATCH(A9,'тм уид'!A:A,0),2, , ,"тм уид")) -> b3596a15-298a-11ea-a23b-00155dd08a09 | C9: Метро | D9: =INDIRECT(ADDRESS(MATCH(C9,'уид произв'!A:A,0),2, , ,"уид произв")) -> a0d7129c-298a-11ea-a23b-00155dd08a09
A10: AGD | B10: =INDIRECT(ADDRESS(MATCH(A10,'тм уид'!A:A,0),2, , ,"тм уид")) -> 1b70c6bc-5980-11ea-a23f-00155dd08a09 | C10: -- | D10: =INDIRECT(ADDRESS(MATCH(C10,'уид произв'!A:A,0),2, , ,"уид произв")) -> e63af9be-5960-11ea-a23f-00155dd08a09
A11: AHMAD | B11: =INDIRECT(ADDRESS(MATCH(A11,'тм уид'!A:A,0),2, , ,"тм уид")) -> b35968ad-298a-11ea-a23b-00155dd08a09 | C11: Метро | D11: =INDIRECT(ADDRESS(MATCH(C11,'уид произв'!A:A,0),2, , ,"уид произв")) -> a0d7129c-298a-11ea-a23b-00155dd08a09
A12: ALAN | B12: =INDIRECT(ADDRESS(MATCH(A12,'тм уид'!A:A,0),2, , ,"тм уид")) -> b3596a36-298a-11ea-a23b-00155dd08a09 | C12: Метро | D12: =INDIRECT(ADDRESS(MATCH(C12,'уид произв'!A:A,0),2, , ,"уид произв")) -> a0d7129c-298a-11ea-a23b-00155dd08a09
A13: ALDEYA | B13: =INDIRECT(ADDRESS(MATCH(A13,'тм уид'!A:A,0),2, , ,"тм уид")) -> b35969e6-298a-11ea-a23b-00155dd08a09 | C13: Метро | D13: =INDIRECT(ADDRESS(MATCH(C13,'уид произв'!A:A,0),2, , ,"уид произв")) -> a0d7129c-298a-11ea-a23b-00155dd08a09
... A147: ECO PACK | B147: =INDIRECT(ADDRESS(MATCH(A147,'тм уид'!A:A,0),2, , ,"тм уид")) -> c7f34833-27e4-11ea-a23b-00155dd08a09 | C147: РОЯЛ ТРЕЙД | D147: =INDIRECT(ADDRESS(MATCH(C147,'уид произв'!A:A,0),2, , ,"уид произв")) -> d30b94e7-41bd-11ea-a23c-00155dd08a09
A148: ECO-EAGLE | B148: =INDIRECT(ADDRESS(MATCH(A148,'тм уид'!A:A,0),2, , ,"тм уид")) -> 02a0da2a-6392-11ea-a240-00155d00f0a7
A149: ECOMIL | B149: =INDIRECT(ADDRESS(MATCH(A149,'тм уид'!A:A,0),2, , ,"тм уид")) -> da63d8f7-3883-11ea-a23c-00155dd08a09 | C149: Метро | D149: =INDIRECT(ADDRESS(MATCH(C149,'уид произв'!A:A,0),2, , ,"уид произв")) -> a0d7129c-298a-11ea-a23b-00155dd08a09
A150: ECOPACK | B150: =INDIRECT(ADDRESS(MATCH(A150,'тм уид'!A:A,0),2, , ,"тм уид")) -> 57178e0e-435c-11ea-a23c-00155dd08a09 | C150: РОЯЛ ТРЕЙД | D150: =INDIRECT(ADDRESS(MATCH(C150,'уид произв'!A:A,0),2, , ,"уид произв")) -> d30b94e7-41bd-11ea-a23c-00155dd08a09
A151: ECOROD | B151: =INDIRECT(ADDRESS(MATCH(A151,'тм уид'!A:A,0),2, , ,"тм уид")) -> b3596b07-298a-11ea-a23b-00155dd08a09 | C151: Метро | D151: =INDIRECT(ADDRESS(MATCH(C151,'уид произв'!A:A,0),2, , ,"уид произв")) -> a0d7129c-298a-11ea-a23b-00155dd08a09
A152: edding | B152: =INDIRECT(ADDRESS(MATCH(A152,'тм уид'!A:A,0),2, , ,"тм уид")) -> f2e4e0cc-2598-11ea-a23b-00155dd08a09 | C152: Віват | D152: =INDIRECT(ADDRESS(MATCH(C152,'уид произв'!A:A,0),2, , ,"уид произв")) -> 602b861c-2596-11ea-a23b-00155dd08a09
A153: EKFOOD | B153: =INDIRECT(ADDRESS(MATCH(A153,'тм уид'!A:A,0),2, , ,"тм уид")) -> b3596acc-298a-11ea-a23b-00155dd08a09 | C153: Метро | D153: =INDIRECT(ADDRESS(MATCH(C153,'уид произв'!A:A,0),2, , ,"уид произв")) -> a0d7129c-298a-11ea-a23b-00155dd08a09
A154: EKOFOOD | B154: =INDIRECT(ADDRESS(MATCH(A154,'тм уид'!A:A,0),2, , ,"тм уид")) -> b3596947-298a-11ea-a23b-00155dd08a09 | C154: Метро | D154: =INDIRECT(ADDRESS(MATCH(C154,'уид произв'!A:A,0),2, , ,"уид произв")) -> a0d7129c-298a-11ea-a23b-00155dd08a09
A155: EKONA | B155: =INDIRECT(ADDRESS(MATCH(A155,'тм уид'!A:A,0),2, , ,"тм уид")) -> b35969f0-298a-11ea-a23b-00155dd08a09 | C155: Метро | D155: =INDIRECT(ADDRESS(MATCH(C155,'уид произв'!A:A,0),2, , ,"уид произв")) -> a0d7129c-298a-11ea-a23b-00155dd08a09
A156: ELITE | B156: =INDIRECT(ADDRESS(MATCH(A156,'тм уид'!A:A,0),2, , ,"тм уид")) -> b3596976-298a-11ea-a23b-00155dd08a09 | C156: Метро | D156: =INDIRECT(ADDRESS(MATCH(C156,'уид произв'!A:A,0),2, , ,"уид произв")) -> a0d7129c-298a-11ea-a23b-00155dd08a09
A157: Elsa | B157: =INDIRECT(ADDRESS(MATCH(A157,'тм уид'!A:A,0),2, , ,"тм уид")) -> 0ff80627-3d0f-11ea-a23c-00155dd08a09 | C157: Епіцентр | D157: =INDIRECT(ADDRESS(MATCH(C157,'уид произв'!A:A,0),2, , ,"уид произв")) -> f3756d12-35fa-11ea-a23b-00155dd08a09
A158: EMILIA | B158: =INDIRECT(ADDRESS(MATCH(A158,'тм уид'!A:A,0),2, , ,"тм уид")) -> c600fc0a-4119-11ea-a23c-00155dd08a09 | C158: Метро | D158: =INDIRECT(ADDRESS(MATCH(C158,'уид произв'!A:A,0),2, , ,"уид произв")) -> a0d7129c-298a-11ea-a23b-00155dd08a09
A159: EMMI | B159: =INDIRECT(ADDRESS(MATCH(A159,'тм уид'!A:A,0),2, , ,"тм уид")) -> b359694c-298a-11ea-a23b-00155dd08a09 | C159: Метро | D159: =INDIRECT(ADDRESS(MATCH(C159,'уид произв'!A:A,0),2, , ,"уид произв")) -> a0d7129c-298a-11ea-a23b-00155dd08a09
A160: ERNST BADER | B160: =INDIRECT(ADDRESS(MATCH(A160,'тм уид'!A:A,0),2, , ,"тм уид")) -> b3596a60-298a-11ea-a23b-00155dd08a09 | C160: Метро | D160: =INDIRECT(ADDRESS(MATCH(C160,'уид произв'!A:A,0),2, , ,"уид произв")) -> a0d7129c-298a-11ea-a23b-00155dd08a09
... A408: PRO SERVISE | B408: =INDIRECT(ADDRESS(MATCH(A408,'тм уид'!A:A,0),2, , ,"тм уид")) -> 694030f4-2650-11ea-a23b-00155dd08a09 | C408: СЕРВІС ПРО | D408: =INDIRECT(ADDRESS(MATCH(C408,'уид произв'!A:A,0),2, , ,"уид произв")) -> d3d228aa-264f-11ea-a23b-00155dd08a09
A409: PROFESSIONAL CLEANING | B409: =INDIRECT(ADDRESS(MATCH(A409,'тм уид'!A:A,0),2, , ,"тм уид")) -> 6bac39fa-62df-11ea-a240-00155d00f0a7
A410: PRONTO | B410: =INDIRECT(ADDRESS(MATCH(A410,'тм уид'!A:A,0),2, , ,"тм уид")) -> b3596838-298a-11ea-a23b-00155dd08a09 | C410: Метро | D410: =INDIRECT(ADDRESS(MATCH(C410,'уид произв'!A:A,0),2, , ,"уид произв")) -> a0d7129c-298a-11ea-a23b-00155dd08a09
A411: PRZYSNACHI | B411: =INDIRECT(ADDRESS(MATCH(A411,'тм уид'!A:A,0),2, , ,"тм уид")) -> b198d2d8-3e76-11ea-a23c-00155dd08a09 | C411: Метро | D411: =INDIRECT(ADDRESS(MATCH(C411,'уид произв'!A:A,0),2, , ,"уид произв")) -> a0d7129c-298a-11ea-a23b-00155dd08a09
A412: PUMPIDUP | B412: =INDIRECT(ADDRESS(MATCH(A412,'тм уид'!A:A,0),2, , ,"тм уид")) -> b3596b02-298a-11ea-a23b-00155dd08a09 | C412: Метро | D412: =INDIRECT(ADDRESS(MATCH(C412,'уид произв'!A:A,0),2, , ,"уид произв")) -> a0d7129c-298a-11ea-a23b-00155dd08a09
A413: QUALITEA | B413: =INDIRECT(ADDRESS(MATCH(A413,'тм уид'!A:A,0),2, , ,"тм уид")) -> b359697b-298a-11ea-a23b-00155dd08a09 | C413: Метро | D413: =INDIRECT(ADDRESS(MATCH(C413,'уид произв'!A:A,0),2, , ,"уид произв")) -> a0d7129c-298a-11ea-a23b-00155dd08a09
A414: QUICKBURY | B414: =INDIRECT(ADDRESS(MATCH(A414,'тм уид'!A:A,0),2, , ,"тм уид")) -> 7ea3bb49-3c4e-11ea-a23c-00155dd08a09 | C414: Метро | D414: =INDIRECT(ADDRESS(MATCH(C414,'уид произв'!A:A,0),2, , ,"уид произв")) -> a0d7129c-298a-11ea-a23b-00155dd08a09
A415: RAID | B415: =INDIRECT(ADDRESS(MATCH(A415,'тм уид'!A:A,0),2, , ,"тм уид")) -> b3596848-298a-11ea-a23b-00155dd08a09 | C415: Метро | D415: =INDIRECT(ADDRESS(MATCH(C415,'уид произв'!A:A,0),2, , ,"уид произв")) -> a0d7129c-298a-11ea-a23b-00155dd08a09
A416: RED BULL | B416: =INDIRECT(ADDRESS(MATCH(A416,'тм уид'!A:A,0),2, , ,"тм уид")) -> d028712b-348f-11ea-a23b-00155dd08a09 | C416: Метро | D416: =INDIRECT(ADDRESS(MATCH(C416,'уид произв'!A:A,0),2, , ,"уид произв")) -> a0d7129c-298a-11ea-a23b-00155dd08a09
A417: RED PISTACHIO | B417: =INDIRECT(ADDRESS(MATCH(A417,'тм уид'!A:A,0),2, , ,"тм уид")) -> b35968e7-298a-11ea-a23b-00155dd08a09 | C417: Метро | D417: =INDIRECT(ADDRESS(MATCH(C417,'уид произв'!A:A,0),2, , ,"уид произв")) -> a0d7129c-298a-11ea-a23b-00155dd08a09
A418: REDMOND | B418: =INDIRECT(ADDRESS(MATCH(A418,'тм уид'!A:A,0),2, , ,"тм уид")) -> f90fea7b-5724-11ea-a23f-00155dd08a09 | C418: Югконтракт | D418: =INDIRECT(ADDRESS(MATCH(C418,'уид произв'!A:A,0),2, , ,"уид произв")) -> 2ca834bb-471f-11ea-a23e-00155dd08a09
A419: REDMOND | B419: =INDIRECT(ADDRESS(MATCH(A419,'тм уид'!A:A,0),2, , ,"тм уид")) -> f90fea7b-5724-11ea-a23f-00155dd08a09 | C419: РОЗЕТКА | D419: =INDIRECT(ADDRESS(MATCH(C419,'уид произв'!A:A,0),2, , ,"уид произв")) -> 96e4ff39-2d5e-11ea-a23b-00155dd08a09
A420: REGAL | B420: =INDIRECT(ADDRESS(MATCH(A420,'тм уид'!A:A,0),2, , ,"тм уид")) -> f2e4e0f8-2598-11ea-a23b-00155dd08a09 | C420: Імпорт Офіс | D420: =INDIRECT(ADDRESS(MATCH(C420,'уид произв'!A:A,0),2, , ,"уид произв")) -> 602b861d-2596-11ea-a23b-00155dd08a09
...

Sheet Сопоставление_коп
A1: НаименованиеТМ | B1: ТМ_УИД | C1: Производитель | D1: Производитель_УИД
A2: "Bob Snail" | B2: 63eae718-4e54-11ea-a23f-00155dd08a0a | C2: Метро | D2: a0d7129c-298a-11ea-a23b-00155dd08a09
A3: 2х3 | B3: 315301c0-5317-11ea-a23f-00155dd08a0a | C3: 2х3 | D3: 927c4fed-499d-11ea-a23e-00155dd08a09
A4: 7 DAYS | B4: 14f1eae0-3b81-11ea-a23c-00155dd08a09 | C4: Метро | D4: a0d7129c-298a-11ea-a23b-00155dd08a09
A5: 7UP | B5: b35968b5-298a-11ea-a23b-00155dd08a09 | C5: Метро | D5: a0d7129c-298a-11ea-a23b-00155dd08a09
A6: 8 ЗЛАКІВ | B6: b359685f-298a-11ea-a23b-00155dd08a09 | C6: Метро | D6: a0d7129c-298a-11ea-a23b-00155dd08a09
A7: 9230SI | B7: d89bbd50-63a4-11ea-a240-00155d00f0a7 | C7: ЕРГОПАК | D7: c89940cf-429f-11ea-a23c-00155dd08a09
A8: ACTIMEL | B8: ed38b08c-27eb-11ea-a23b-00155dd08a09 | C8: Метро | D8: a0d7129c-298a-11ea-a23b-00155dd08a09
A9: AERO | B9: b3596a15-298a-11ea-a23b-00155dd08a09 | C9: Метро | D9: a0d7129c-298a-11ea-a23b-00155dd08a09
A10: AGD | B10: 1b70c6bc-5980-11ea-a23f-00155dd08a09 | C10: -- | D10: e63af9be-5960-11ea-a23f-00155dd08a09
A11: AHMAD | B11: b35968ad-298a-11ea-a23b-00155dd08a09 | C11: Метро | D11: a0d7129c-298a-11ea-a23b-00155dd08a09
A12: ALAN | B12: b3596a36-298a-11ea-a23b-00155dd08a09 | C12: Метро | D12: a0d7129c-298a-11ea-a23b-00155dd08a09
... A147: ECO PACK | B147: c7f34833-27e4-11ea-a23b-00155dd08a09 | C147: РОЯЛ ТРЕЙД | D147: d30b94e7-41bd-11ea-a23c-00155dd08a09
A148: ECO-EAGLE | B148: 02a0da2a-6392-11ea-a240-00155d00f0a7
A149: ECOMIL | B149: da63d8f7-3883-11ea-a23c-00155dd08a09 | C149: Метро | D149: a0d7129c-298a-11ea-a23b-00155dd08a09
A150: ECOPACK | B150: 57178e0e-435c-11ea-a23c-00155dd08a09 | C150: РОЯЛ ТРЕЙД | D150: d30b94e7-41bd-11ea-a23c-00155dd08a09
A151: ECOROD | B151: b3596b07-298a-11ea-a23b-00155dd08a09 | C151: Метро | D151: a0d7129c-298a-11ea-a23b-00155dd08a09
A152: edding | B152: f2e4e0cc-2598-11ea-a23b-00155dd08a09 | C152: Віват | D152: 602b861c-2596-11ea-a23b-00155dd08a09
A153: EKFOOD | B153: b3596acc-298a-11ea-a23b-00155dd08a09 | C153: Метро | D153: a0d7129c-298a-11ea-a23b-00155dd08a09
A154: EKOFOOD | B154: b3596947-298a-11ea-a23b-00155dd08a09 | C154: Метро | D154: a0d7129c-298a-11ea-a23b-00155dd08a09
A155: EKONA | B155: b35969f0-298a-11ea-a23b-00155dd08a09 | C155: Метро | D155: a0d7129c-298a-11ea-a23b-00155dd08a09
A156: ELITE | B156: b3596976-298a-11ea-a23b-00155dd08a09 | C156: Метро | D156: a0d7129c-298a-11ea-a23b-00155dd08a09
A157: Elsa | B157: 0ff80627-3d0f-11ea-a23c-00155dd08a09 | C157: Епіцентр | D157: f3756d12-35fa-11ea-a23b-00155dd08a09
A158: EMILIA | B158: c600fc0a-4119-11ea-a23c-00155dd08a09 | C158: Метро | D158: a0d7129c-298a-11ea-a23b-00155dd08a09
A159: EMMI | B159: b359694c-298a-11ea-a23b-00155dd08a09 | C159: Метро | D159: a0d7129c-298a-11ea-a23b-00155dd08a09
A160: ERNST BADER | B160: b3596a60-298a-11ea-a23b-00155dd08a09 | C160: Метро | D160: a0d7129c-298a-11ea-a23b-00155dd08a09
... A331: MILKY WAY | B331: 3f58e034-5a44-11ea-a23f-00155dd08a09 | C331: Метро | D331: a0d7129c-298a-11ea-a23b-00155dd08a09
A332: MILLENIUM | B332: #N/A | C332: Метро | D332: a0d7129c-298a-11ea-a23b-00155dd08a09
A333: MILLENNIUM | B333: b3596907-298a-11ea-a23b-00155dd08a09 | C333: Метро | D333: a0d7129c-298a-11ea-a23b-00155dd08a09
A334: MIRINDA | B334: b35969b2-298a-11ea-a23b-00155dd08a09 | C334: Метро | D334: a0d7129c-298a-11ea-a23b-00155dd08a09
A335: MISSO | B335: b3596a80-298a-11ea-a23b-00155dd08a09 | C335: Метро | D335: a0d7129c-298a-11ea-a23b-00155dd08a09
A336: Misso | B336: b3596a80-298a-11ea-a23b-00155dd08a09 | C336: розетка | D336: 96e4ff39-2d5e-11ea-a23b-00155dd08a09
A337: MIX | B337: f2e4e0ef-2598-11ea-a23b-00155dd08a09 | C337: Імпорт Офіс | D337: 602b861d-2596-11ea-a23b-00155dd08a09
A338: MIX&GO | B338: b3596ac4-298a-11ea-a23b-00155dd08a09 | C338: Метро | D338: a0d7129c-298a-11ea-a23b-00155dd08a09
A339: Mlesna | B339: b1fd444e-3ea6-11ea-a23c-00155dd08a09 | C339: ФОП Матюхова Юлія Вячеславівна | D339: aafc1d13-3ea6-11ea-a23c-00155dd08a09
A340: MOLENDAM | B340: b3596928-298a-11ea-a23b-00155dd08a09 | C340: Метро | D340: a0d7129c-298a-11ea-a23b-00155dd08a09
A341: MOSQUITALL | B341: 72c74eaa-59fe-11ea-a23f-00155dd08a09 | C341: 27 юа | D341: 648330d8-3914-11ea-a23c-00155dd08a09
A342: MR MUSCLE | B342: b3596936-298a-11ea-a23b-00155dd08a09 | C342: Метро | D342: a0d7129c-298a-11ea-a23b-00155dd08a09
A343: MYLOVA | B343: b3596a54-298a-11ea-a23b-00155dd08a09 | C343: Метро | D343: a0d7129c-298a-11ea-a23b-00155dd08a09
A344: NABEGHLAVI | B344: a96aebf3-35ec-11ea-a23b-00155dd08a09 | C344: Метро | D344: a0d7129c-298a-11ea-a23b-00155dd08a09
...
